<mujoco model="foot">
  <include file="./common/skybox.xml"/>
  <include file="./common/visual.xml"/>
  <include file="./common/materials.xml"/>

  <compiler settotalmass="2"/>

  <default>
    <default class="foot">
      <joint limited="true" damping=".01" armature=".1" stiffness="8" type="hinge" axis="0 1 0"/>
      <geom contype="1" conaffinity="1" condim="3" friction=".4 .1 .1" material="self"/>
    </default>
    <default class="free">
      <joint limited="false" damping="0" armature="0" stiffness="0"/>
    </default>
    <motor ctrllimited="true" ctrlrange="-1 1"/>
  </default>

  <statistic center="0 0 .7" extent="2"/>

  <option timestep="0.01"/>

  <worldbody>
    <geom name="ground" type="plane" conaffinity="1" pos="98 0 0" size="100 .8 .5" material="grid"/>
    <body name="torso" pos="0 0 .7" childclass="foot">
      <light name="light" pos="0 0 2" mode="trackcom"/>
      <camera name="side" pos="0 -3 0" quat="0.707 0.707 0 0" mode="trackcom"/>
      <camera name="back" pos="-1.8 -1.3 0.8" xyaxes="0.45 -0.9 0 0.3 0.15 0.94" mode="trackcom"/>
      <joint name="rootx" type="slide" axis="1 0 0" class="free"/>
      <joint name="rootz" type="slide" axis="0 0 1" class="free"/>
      <joint name="rooty" type="hinge" axis="0 1 0" class="free"/>
      <geom name="torso" type="capsule" fromto="-.1 0 0 .1 0 0" size="0.046" solref="-1 0"/>

      <body name="ffoot" pos=".1 0 0">
      <joint name="ffoot" range="-28 28" stiffness="0" damping="0"/>
      <geom name="ffoot" type="capsule" pos="-.07 0 -.12" euler="0 -15 0" size="0.046 .094"/>
      </body>

      <body name="bfoot" pos="-.1 0 0">
      <joint name="bfoot" range="-230 50" stiffness="0" damping="0"/>
      <geom name="bfoot" type="capsule" pos=".1 0 -.13" euler="0 -15 0" size="0.046 .094"/>

      </body>
    </body>
  </worldbody>

  <sensor>
    <subtreelinvel name="torso_subtreelinvel" body="torso"/>
  </sensor>

  <actuator>
    <motor name="ffoot" joint="ffoot" gear="30" />
    <motor name="bfoot" joint="bfoot" gear="60" />
  </actuator>
</mujoco>
