<mujoco model="pendulum">
  <include file="./common/visual.xml"/>
  <include file="./common/skybox.xml"/>
  <include file="./common/materials.xml"/>

  <option timestep="0.01" integrator="RK4">
    <flag contact="disable" energy="enable"/>
  </option>

  <default>
    <default class="pole">
      <joint type="hinge" axis="0 1 0"  damping="0.0"/>
      <geom type="capsule" fromto="0 0 0 0 0 1" size="0.045" material="self" mass="1"/>
    </default>
  </default>

  <worldbody>
    <light name="light" pos="0 0 6"/>
    <camera name="fixed" pos="0 -4 1" zaxis="0 -1 0"/>
    <camera name="lookatpole" mode="targetbody" target="pole_1" pos="0 -2 2"/>
    <geom name="floor" pos="0 0 -0.05" size="4 4 .2" type="plane" material="grid"/>
    <body name="pole_1" childclass="pole" pos='0 0 1.0'>
      <joint name="hinge_1"/>
      <geom name="pole_1"/>

      <!-- <body name="pole_1" childclass="pole" pos='0 0 1.0'>
        <joint name="hinge_1"/>
        <geom name="pole_1"/>
      </body> -->
    </body>
  </worldbody>

  <actuator>
    <motor name="torque" joint="hinge_1" gear="40" ctrlrange="-1 1" ctrllimited="true"/>
  </actuator>
</mujoco>
